Workbook
Name _Hlk9994321: 'page 1'!#REF!

Sheet cover
A1: Reference 1- Confirmation List between Ship - Shore
C17: CONFIRMATION LIST BETWEEN SHIP- SHORE
C18: For
C19: ="..................."&'page 1'!AC7&"..................." -> ......................................
C20: and
C21: "LNG Map Ta Phut Terminal 2"
AH56: (4) Clearence between flange and ship's side:

Sheet sumary&directory
A1: Confirmation List Between Ship-Shore (Berth # 1) | AU1: Page
AU2: 1/ 9
A3: SUMMARY CRITICAL TOPICS | Y3: CONTENTS
A4: ITEM | D4: Description | K4: Value | Q4: Condition | T4: Remaks / Result | AI4: PAGE
A5: Ship Major Information | D5: Draft Ballast OPTIMOOR | K5: ='page 1'!AD33 -> 0 | Q5: Margin Gangway >0.3m | Z5: I. | AA5: General Information | AI5: 1 | AL5: Appendix
D6: Draft Loaded OPTIMOOR | K6: ='page 1'!AD34 -> 0 | Q6: <=12.2m | AA6: 1.General
D7: Gas Management Primary | K7: ='page 1'!AC18 -> 0 | Q7: At least 1 System | AA7: 2. Max. Size of Vessel | AL7: Appendix A | AN7: : | AO7: Mooring Arrangement
D8: Gas Management Secondary | K8: ='page 1'!AC19 -> 0 | Q8: At least 1 System | AL8: Appendix B | AN8: : | AO8: Spool piece Drawing
A9: MOORING INFORMATION | D9: Fender Reaction Ballast | K9: ='page 2'!AZ11&", "&'page 2'!AZ12&", "&'page 2'!AZ13&", "&'page 2'!AZ14 -> #DIV/0! | Q9: - | T9: ='page 2'!AW5 -> Acceptable | Z9: II. | AA9: Fender / Flat Body | AI9: 2
D10: Fender Reaction Loaded | K10: ='page 2'!AZ24&", "&'page 2'!AZ25&", "&'page 2'!AZ26&", "&'page 2'!AZ27 -> #DIV/0! | Q10: - | T10: ='page 2'!AW18 -> Acceptable | AA10: 1. Arrangement
D11: Berthing Energy & Fender Absorb Percentage | K11: ='page 2'!AA41 -> , 0% | Q11: - | T11: ='page 2'!AW41 -> Acceptable | AA11: 2. Fender / Contact Area design
D12: Type of MOORING Rope | K12: ='page 2'!Z64&" "&'page 2'!AB64 | Q12: - | AA12: 3. Berthing Energy
D13: Type of Tail Rope | K13: ='page 2'!AG64 -> 0 | Q13: - | AA13: 4. Approaching Speed Meter
D14: Mooring Pattern | K14: ='Appendix A'!B31 -> FWD : X/X/X/X :::::::: X/X/X/X AFT | Q14: -
A15: Gangway & Manifolds | D15: Gangway Area Clearance (Dimension only) | K15: ='page 3'!AE26&" x "&'page 3'!AE27&" m." -> 0 x 0 m. | Q15: Positive Value | T15: ='page 3'!AB23 -> **Unacceptable** | Z15: III. | AA15: Mooring Arrangement | AI15: 2
D16: Gangway Margin Upper, Lower | K16: ="Upper "&'page 3'!AE39&" m. , Lower "&'page 3'!AE40&" m." -> Upper 18.7 m. , Lower -12.6 m. | Q16: Margin Gangway >0.3m | T16: ='page 3'!AA41 -> **Unacceptable** | AA16: 1. Mooring Facilities (Hooks / Winches)
D17: ESD By-Pass Line | K17: ='page 4'!Z49 -> 0 | Q17: - | AA17: 2. Mooring Layout
D18: Manifold Spacing | K18: ='page 4'!Z47&", "&'page 4'!AB47&", "&'page 4'!AD47&", "&'page 4'!AF47 -> , , , | Q18: 2.5< X <3.5 (m) | T18: ='page 4'!AG46 -> **Unacceptable** | AA18: 3. Weather Criteria for Mooring force calculation
D19: Maximum Flowrate | K19: ='page 4'!AC56 -> 0
D20: Maximum Manifold Pressure (Operate) | K20: ='page 4'!AF56 -> 0 | Q20: Leak and Purge at 5&1 barg at Liq&Vap. | Z20: IV. | AA20: Gangway / Support | AI20: 3
D21: Manifold Margin Upper, Lower | K21: ="Upper "&'page 5'!AE12&" m. , Lower "&'page 5'!AE13&" m." -> Upper 23.5 m. , Lower -18 m. | Q21: Margin Manifold >0.3m | T21: ='page 5'!AA14 -> **Unacceptable** | AA21: 1. Position of Gangway / Details
A22: Ship&Shore Link | D22: SSL Fiber Optic connector type | K22: ='page 5'!Z48 -> 0 | Q22: 6 Core connector | AA22: 2. Gangway Working Area
D23: SSL Electric connector type | K23: ='page 5'!Z55 -> 0 | Q23: 37 ways pin
A24: CTMS | D24: Primary Level CTMS | K24: ='page 6'!Y7 -> 0 | Q24: +- 7.5 mm. | T24: ='page 6'!AA7 -> Acceptable | Z24: V. | AA24: Unloading Arm / Cargo Pump / Compressor | AI24: 4-5
D25: Secondary Level CTMS | K25: ='page 6'!Y15 -> 0 | Q25: +- 7.5 mm. | T25: ='page 6'!AA15 -> Acceptable | AA25: 1. Unloading Arm / Cargo Pump
A26: Spool Piece | D26: Number of Spool Piece (RDP, SDP) on board | K26: ='Appendix B'!I45 -> 0 | Q26: >=4 items | AA26: 2. Uoading Arm / Manifold Layout
A27: Sunken Bitts | D27: Higher Fender Ballast | K27: ='page 3'!AP38 -> 0 | N27: m | Q27: 3.6 m. - 7.6 from m. water Surface | T27: ='page 3'!AO40 -> **Unacceptable** | AA27: 3. Unloading Performance
D28: Higher Fender Loaded | K28: ='page 3'!AS38 -> 0 | N28: m | AA28: 4. Unloading Arm Working Range
D29: Lower Fender Ballast | K29: ='page 3'!AP39 -> 0 | N29: m | T29: ='page 3'!AO41 -> **Unacceptable** | AA29: 5. Instrument Hose (Nitrogen Air / Fresh Water)
D30: Lower Fender Loaded | K30: ='page 3'!AS39 -> 0 | N30: m
A31: Please input Vessel information following Blank in yellow through page1 --> Appendix B | Z31: VI. | AA31: Emergency Shut Down System | AI31: 5
AA32: 1. Optical Fiber System
AA33: 2. Pneumatic System
AA34: 3. Electric System
AA35: 4. ESD Activation
Z37: VII. | AA37: CTMS On board | AI37: 6
AA38: 1. Level measurement devices (Primary)
AA39: 2. Level measurement devices (Secondary)
AA40: 3. Temperature measurement devices
AA41: 4. Pressure measurement devices
...

Sheet page 1
A1: Confirmation List Between Ship-Shore (Berth # 1) | AV1: Page
AV2: 2 / 9
A3: Items | G3: Shore Specification | V3: Ship Specification | AJ3: Remarks
A4: I. General information
A6: 1. General | G6: 1.Terminal Name & Etc | V6: 1.Ship Name & Etc
G7: - Country | N7: : | O7: Thailand | V7: - Ship's Name | AB7: :
G8: - Port name | O8: Nong Fab LNG Receiving Terminal | V8: - IMO number | AB8: :
G9: - Berth name | O9: Nong Fab LNG Receiving Terminal Berth #1 | V9: - Call Sign | AB9: :
G10: - Name of terminal operating company | O10: PTT LNG/PE LNG COMPANY LIMITED | V10: - Flag Country | AB10: :
G11: - Name / title of person to contact regarding terminal information | V11: - Port of registry | AB11: :
H12: Name | L12: : | M12: Narudech S / Nawi T | V12: - Year Built (Input only year) | AB12: :
H13: Address | L13: : | M13: 8/2, Rong pui Road, Map Ta Phut Industrial Estate | V13: - Owner | AB13: :
M14: Muang District, Rayong 21150 Thailand | V14: - Operator | AB14: :
H15: Tel | L15: : | M15: + 66 (0) 38 978 200 ext. 8322 | V15: - Type of Cargo Containment System | AB15: :
H16: H/P (hotline) | L16: : | M16: +66 (0) 95 436 1188 / +66 (0) 93 734 7185 | V16: - Tank Capacity (total 100% full) | AB16: :
H17: Fax | L17: : | M17: + 66 (0) 38 978 290 | V17: - Classification Society | AB17: :
H18: E-mail | L18: : | M18: narudech.s@pttlng.com / nawi.t@pttlng.com | V18: - Gas management System | AA18: 1st (Primary) | AB18: : | AE18: **During Discharging Operation**
G19: - Year LNG operations commenced | L19: : | M19: 2022 | V19: - Gas management System | AA19: 2nd (Secondary) | AB19: : | AE19: **During Discharging Operation**
G20: - Import & Export | L20: : | M20: Import
A23: 2. Max. Size of Vessel | D23: Qmax
G24: 1.Max. Size of Vessel Acceptable | V24: 1.Ship Major Dimensions
G25: (1) LOA | K25: : | L25: 345.3 | N25: m | V25: (1) LOA | AC25: : | AE25: m
G26: (2) Breadth | K26: : | L26: 55 | N26: m | V26: (2) LBP | AC26: : | AE26: m
G27: (3a) Draft loaded | K27: : | L27: 12.2 | N27: m | V27: (3) Breadth (Moulded) | AC27: : | AE27: m
G28: (3b) Draft ballast | K28: : | L28: 10 | N28: m | V28: (4) Depth (Moulded) | AC28: : | AE28: m
G29: (4a) Displacement loaded | K29: : | L29: 178220 | N29: ton | AB29: Upper deck height above BL | AC29: : | AE29: m | AF29: (For Gangway margin calculation)
G30: (4b) Displacement ballast | L30: 141000 | N30: ton | AB30: Manifold heigh above BL | AC30: : | AE30: m | AF30: (For Manifold margin calculation)
G31: (5) Cargo Volume | K31: : | L31: 266000 | N31: m³
G32: (6) Main Alongside | K32: : | L32: Star board
V33: (5) Draft | AA33: (Ballast) | AC33: : | AE33: m | AG33: ← Refer from OPTIMOOR
AA34: (Loaded) | AC34: : | AE34: m | AG34: ← Refer from OPTIMOOR
V36: (6) Displacement | AA36: (Loaded) | AC36: : | AE36: ton
V38: (7) Gross tonnage | AC38: : | AE38: ton
V41: (8) Sunken bitts (If any) | AB41: Higher height above BL | AC41: : | AE41: m
AB42: Lower height above BL | AC42: : | AE42: m

Sheet page 2
A1: Confirmation List Between Ship-Shore (Berth # 1) | AW1: Page
AW2: 3 / 9
A3: Items | G3: Shore Specification | W3: Ship Specification | AK3: Remarks
A4: II. Fender / Flat Body
AK5: Table 1. Fender Reaction Force Calculation at Ballast Draft (Refer to Trelleborg report) | AW5: {=IF(OR(AS11:AT14>AU11:AV14),"**Unacceptable**","Acceptable")} -> Acceptable
A6: 1. Arrangement | G6: 1. Fender Arrangement & Details | N6: Vapour Arm / Vapour Manifold | V6: (unit : m) | W6: 1. Flat Body | AJ6: (unit : m) | AK6: Fender No. | AM6: Fender Reaction Force (ton) | AO6: Fender Area Contact (m²) | AQ6: Fender Area Contact (%) | AS6: Actual Face Pressure (ton/m²) | AU6: Allowable Hull Pressure (ton/m²) | AW6: Remark (%)
W7: (1) Vapour Manifold Offset from midhip LBP/2 (Fwd = minus - /Af t= plus +) | AH7: : | AJ7: m
AK11: F1 | AO11: 44.9 | AQ11: 100 | AS11: =AM11/(AO11*AQ11%) -> 0 | AU11: =$AC$33 -> 0 | AW11: =AS11/AU11 -> #DIV/0! | AZ11: =ROUND(AW11*100,0) -> #DIV/0!
AK12: F2 | AO12: 44.9 | AQ12: 100 | AS12: =AM12/(AO12*AQ12%) -> 0 | AU12: =$AC$33 -> 0 | AW12: =AS12/AU12 -> #DIV/0! | AZ12: =ROUND(AW12*100,0) -> #DIV/0!
U13: Fender Face | AK13: F3 | AO13: 44.9 | AQ13: 100 | AS13: =AM13/(AO13*AQ13%) -> 0 | AU13: =$AC$33 -> 0 | AW13: =AS13/AU13 -> #DIV/0! | AZ13: =ROUND(AW13*100,0) -> #DIV/0!
I14: F1 | J14: F2 | Q14: F3 | S14: F4 | AK14: F4 | AO14: 44.9 | AQ14: 100 | AS14: =AM14/(AO14*AQ14%) -> 0 | AU14: =$AC$33 -> 0 | AW14: =AS14/AU14 -> #DIV/0! | AZ14: =ROUND(AW14*100,0) -> #DIV/0!
AK15: Remark : | AM15: Percentage of actual face pressure to allowable hull pressure
AM16: The actual face pressure shall be less than the allowable hull pressure
I17: 115
AK18: Table 2. Fender Reaction Force Calculation at Loaded Draft (Refer to Trelleborg report) | AW18: {=IF(OR(AS24:AT27>AU24:AV27),"**Unacceptable**","Acceptable")} -> Acceptable
AK19: Fender No. | AM19: Fender Reaction Force (ton) | AO19: Fender Area Contact (m²) | AQ19: Fender Area Contact (%) | AS19: Actual Face Pressure (ton/m²) | AU19: Allowable Hull Pressure (ton/m²) | AW19: Remark (%)
S20: Deck Level CDL(+) 8.00 m
S22: CL Fender CDL(+) 6.25 m
I24: 7.3 | S24: HAT Level CDL(+) 3.50 m | AK24: F1 | AO24: 44.9 | AQ24: 100 | AS24: =AM24/(AO24*AQ24%) -> 0 | AU24: =$AC$33 -> 0 | AW24: =AS24/AU24 -> #DIV/0! | AZ24: =ROUND(AW24*100,0) -> #DIV/0!
X25: Length of Flat Body From Vapour Manifold | AK25: F2 | AO25: 44.9 | AQ25: 100 | AS25: =AM25/(AO25*AQ25%) -> 0 | AU25: =$AC$33 -> 0 | AW25: =AS25/AU25 -> #DIV/0! | AZ25: =ROUND(AW25*100,0) -> #DIV/0!
X26: Details | AD26: Fwd Part | AG26: Aft Part | AK26: F3 | AO26: 44.9 | AQ26: 100 | AS26: =AM26/(AO26*AQ26%) -> 0 | AU26: =$AC$33 -> 0 | AW26: =AS26/AU26 -> #DIV/0! | AZ26: =ROUND(AW26*100,0) -> #DIV/0!
S27: LAT Level CDL(+) 0.50 m | X27: Length of Ballast Draft | AD27: 1 | AG27: 2 | AK27: F4 | AO27: 44.9 | AQ27: 100 | AS27: =AM27/(AO27*AQ27%) -> 0 | AU27: =$AC$33 -> 0 | AW27: =AS27/AU27 -> #DIV/0! | AZ27: =ROUND(AW27*100,0) -> #DIV/0!
X28: Length of Loaded Draft | AD28: 3 | AG28: 4 | AK28: Remark : | AM28: Percentage of actual face pressure to allowable hull pressure
G29: (1) Fender Face Contact Area | K29: : | L29: 44.9 | N29: m² | O29: Full face contact | X29: Length of upper deck part (for reference) | AD29: 5 | AG29: 6 | AM29: The actual face pressure shall be less than the allowable hull pressure
A32: 2. Fender / Contact Area design | G32: 1. Maximum Design (Fender) | W32: 1. Maximum Fender Contact Pressure
G33: (1) Face Pressure | L33: : | M33: 150 | O33: kN/m² | P33: or | Q33: 15.3 | S33: ton/m² | W33: (1) Allowable Hull Pressure | AB33: : | AD33: ton/m² | AE33: (Refer to PIANC 2002, page 25)
G34: (2) Reaction Force | L34: : | M34: 5000.8 | O34: kN | P34: or | Q34: =ROUND(M34/9.81,1) -> 509.8 | S34: tons force | W34: (2) Calculation Result | AB34: : | AC34: Refer to Table 1 & 2 on the right column
G35: (3) Reaction Force Limit (+10%) | L35: : | M35: 5503.2 | O35: kN | P35: or | Q35: =ROUND(M35/9.81,1) -> 561 | S35: tons force
G36: (4) Energy Absorption | L36: : | M36: 5489.4 | O36: kNm | P36: or | Q36: 617 | S36: tons-m
G37: (5) Energy Absorption Limit (-10%) | L37: : | M37: =M36*0.9 -> 4940.46 | O37: kNm | P37: or | Q37: 555.4 | S37: tons-m
G38: (6) Fender Type | L38: : | M38: SCK 2500 E2.9 | O38: rectangular shape
W40: 1. Berthing Energy Calculations at Loaded Draft
A41: 3. Berthing Energy | G41: 1. Berthing Energy Calculations (Design) | W41: (1) Calculation Result | AA41: =AS46&", "&BA46&"%" -> , 0% | AC41: : | AD41: Refer to Table 3 | AK41: Table 3. Berthing Energy Calculation at Loaded Draft (in accordance with BS 6349) | AW41: =IF(AS46>AU46,"**Unacceptable**","Acceptable") -> Acceptable
W42: Approaching Speed Meter | AK42: MD | AM42: VB | AN42: AB | AO42: CM | AP42: CE | AQ42: CC | AR42: CS | AS42: Berthing Energy (tons-m) | AU42: Energy absorption of Fender (tons-m) | AW42: Remark (%)
H43: Design Particulars | N43: Details | W43: (1) Position | Z43: : | AA43: Vapour Arm / Vapour Manifold | AJ43: (unit : m)
H44: Capacity (m³) | N44: 130000 | P44: 165000 | R44: 266,000
H45: Type | N45: MOSS | P45: MOSS | R45: Membrane
H46: Displacement at loaded draft (tonnes) | N46: 96262 | P46: 115000 | R46: 178193 | AK46: ='page 1'!AD36 -> 0 | AM46: 0.1 | AN46: 6 | AO46: 1.75 | AP46: 0.736 | AQ46: 1 | AR46: 1 | AU46: 555.4 | AW46: =(AS46/AU46)*100 -> 0 | AZ46: =AS46 -> 0 | BA46: =ROUND(AW46,2) -> 0
H47: Berthing Velocity (m/s) | N47: 0.15 | P47: 0.15 | R47: 0.15
H48: Berthing Angle (degree) | N48: 7 | P48: 7 | R48: 7 | AK48: Remark : | AM48: Percentage of Berthing Energy to Energy absorption of Fender
...

Sheet page 3
A1: Confirmation List Between Ship-Shore (Berth # 1) | AT1: Page
AT2: 4 / 9
A3: Items | G3: Shore Specification | U3: Ship Specification | AI3: Remarks
A4: IV. Gangway / Support
AA5: STB A/S
A6: 1. Position of Gangway / Details | G6: 1. Gangway Position | K6: Vapour Arm / Vapour Manifold | T6: (unit : m) | U6: 1. Gangway Landing Position | Z6: Vapour Arm / Vapour Manifold | AH6: (unit : m)
N7: 18.5
K15: 4.5 | S15: Fender Face | AG15: Fender Face
S16: Ship Side | AG16: Ship Side
L17: max 4.6 m | AC17: Landing space on upper deck
K19: SHIP FWD | V19: SHIP FWD
G21: 2. Detail of Gangway
G22: (1) Type | K22: : | L22: Telescopic Type operated by Hydraulic System
G23: (2) Interface Part | K23: : | L23: Bulwark Ladder | U23: (1) | W23: : | Y23: m | AA23: Result | AB23: =IF(AND((X26-X25)>=0.6,(X24-X23)>=2.45),"Acceptable","**Unacceptable**") -> **Unacceptable**
G24: (3) Design Condition | K24: : | L24: Max windspeed 45m/s | U24: (2) | W24: : | Y24: m
G25: (3) Design Load | K25: : | L25: 250kg/m2 | N25: Live load | U25: (3) | W25: : | Y25: m | AB25: Gangway Landing Area
G26: (4) Angle of Gangway | K26: : | L26: Upward | O26: 10 | U26: (4) | W26: : | Y26: m | AC26: Length | AD26: : | AE26: =X24-X23 -> 0 | AF26: m
K27: : | L27: Down ward | O27: 20 | AC27: Width | AD27: : | AE27: =X26-X25 -> 0 | AF27: m
K28: : | L28: Left / Right | O28: 15
K29: : | L29: drift allowance | O29: 7.3
A32: 2. Gangway Working Area | G32: 1. Working Area | T32: (unit : m) | U32: 1. Gangway working range and support | AH32: (unit : m) | AI32: 2. Sunken bitts for Emergency Departure
A33: Sunken bitt heigh above BL | G33: (1) Working Range of Gangway | U33: (1) Gangway Compatibility
AB34: Reference Page1 Ship Major Dimensions | AP34: Reference Page1 Ship Major Dimensions
H35: Item | L35: From | P35: (m) | R35: Remark | V35: Upper deck height above BL | AB35: ='page 1'!AD29 -> 0 | AJ35: Higher Sunken Bitt height above BL | AP35: ='page 1'!AD41 -> 0
H36: Working Range of Gangway | L36: High (above CDL) | O36: 1 | P36: 22.7 | V36: Ballast draft | AA36: 5 | AB36: ='page 1'!AD33 -> 0 | AJ36: Lower Sunken Bitt height above BL | AP36: ='page 1'!AD42 -> 0
L37: Low (above CDL) | O37: 2 | P37: 12.1 | V37: Loaded draft | AA37: 6 | AB37: ='page 1'!AD34 -> 0 | AJ37: Height above water surface | AP37: Ballast Draft | AS37: Loaded draft
H38: Tide Level | L38: High (above CDL) | O38: 3 | P38: 3.5 | V38: Safety clearance (m) | AB38: Normal | AE38: With Heave & List | AJ38: Higher Sunken Bitt | AO38: 7,8 | AP38: =AP35-'page 1'!AD33 -> 0 | AS38: =AP35-'page 1'!AD34 -> 0
L39: Low (above CDL) | O39: 4 | P39: 0.5 | V39: Upper Position | AB39: =P36-(AB35-AB36+P38) -> 19.2 | AE39: =AB39-0.5 -> 18.7 | AJ39: Lower Sunken Bitt | AO39: 9,10 | AP39: =AP36-'page 1'!AD33 -> 0 | AS39: =AP36-'page 1'!AD34 -> 0
H40: Heave & List | P40: 0.5 | V40: Lower Position | AB40: =(AB35-AB37)-P37 -> -12.1 | AE40: =AB40-0.5 -> -12.6 | AJ40: Result : Higher position | AO40: =IF(OR(AP38>7.6,AS38>7.6,AS38<3.6),"**Unacceptable**","Acceptable") -> **Unacceptable**
V41: Result | AA41: =IF(OR(AB39<0.3,AE39<0.3,AB40<0.3,AE40<0.3),"**Unacceptable**","Acceptable") -> **Unacceptable** | AJ41: Result : Lower position | AO41: =IF(OR(AP39>7.6,AS39>7.6,AS39<3.6),"**Unacceptable**","Acceptable") -> **Unacceptable**
H43: HIGH LEVEL | V43: HIGH LEVEL
G44: WORKING RANGE OF GANGWAY | U44: WORKING RANGE OF GANGWAY
I56: LOW LEVEL | W56: LOW LEVEL

Sheet page 4
A1: Confirmation List Between Ship-Shore (Berth # 1) | AT1: Page
AT2: 5 / 9
A3: Items | G3: Shore Specification | U3: Ship Specification | AI3: Remarks
A4: V. Unloading Arm / Cargo Pump / Compressor
A6: 1. Unloading Arm / Cargo Pump | G6: 1. Unloading Flow Rate | U6: 1. Cargo Pump Spec.
G7: (1) Flow Rate | U7: (1) Cargo Pump | Z7: : | AB7: m³ / hr | AC7: x | AE7: sets
G8: - | H8: Vapour | K8: : | L8: 14000 | N8: m³/h/arm | U8: (2) Stripping / Spray Pump | Z8: : | AB8: m³ / hr | AC8: x | AE8: sets
G9: - | H9: Liquid | K9: : | L9: 4000 | N9: m³/h/arm | U9: (3) Em'cy Cargo Pump | Z9: : | AB9: m³ / hr | AC9: x | AE9: sets
G11: (2) Numbers
G12: - | H12: Vapour | K12: : | L12: 1 | M12: set
G13: - | H13: Liquid | K13: : | L13: 4 | M13: set | N13: 3 liquid + 1 hybrid | U13: 2. Flang Spec.
U14: - | V14: Vapour | Z14: :
G15: (3) Size | U15: - | V15: Liquid | Z15: :
G16: - | H16: Vapour | K16: : | L16: 20 | M16: inches
G17: - | H17: Liquid | K17: : | L17: 20 | M17: inches | U17: 3. Cargo Strainer
U18: - | V18: Vapour | Z18: : | AB18: mesh
G19: (4) Quick Release Couple | K19: : | L19: Yes | U19: - | V19: Liquid | Z19: : | AB19: mesh
G21: (5) Flange Spec. | U21: 4. High Duty Compressor
G22: - | H22: Vapour | K22: : | L22: 16" QCDC | U22: (1) Number | Z22: : | AC22: Units
G23: - | H23: Liquid | K23: : | L23: 16" QCDC | U23: (2) Capacity | Z23: : | AC23: m³ / hr
U24: (3) Pressure | Z24: : | AC24: bar g
G25: (6) Strainer Mesh
G26: - | H26: Vapour | K26: : | L26: N/A | M26: mesh | U26: 5. Gas Management System | AB26: Unit
G27: - | H27: Liquid | K27: : | L27: N/A | M27: mesh | U27: (1) GCU | Y27: Capacity | Z27: : | AC27: time to | AD27: Start | AF27: Stop | AH27: Min
U28: (2) Gas Burning | Y28: Capacity | Z28: : | AC28: time to | AD28: Start | AF28: Stop | AH28: Min
U29: (3) Reliquefaction plant | Y29: Capacity | Z29: : | AC29: time to | AD29: Start | AF29: Stop | AH29: Min
A31: 2. Unloading Arms / Manifold Layout | G31: 1. Unloading Arms Arrangement | U31: 1. Manifold Layout (Plan) | AH31: (unit : m)
J32: A | K32: B | M32: E | N32: C | P32: D
G42: BOW | S42: STERN
J43: L1 | K43: L2 | M43: V | N43: L3 | P43: L4
K46: Vapour Arm / Vapour Manifold | AG46: =IF(OR(Z47<S48,AB47<S48,AD47<S48,AF47<S48,Z47>S49,AB47>S49,AD47>S49,AF47>S49),"**Unacceptable**","Acceptable") -> **Unacceptable**
U47: 2. Manifold Spacing (metre) | Y47: :
G48: - Simultaneous connection of 4 Unloading Arms at Minimum Manifold Spacing | R48: : | S48: 2.5 | T48: m
G49: - Simultaneous connection of 4 Unloading Arms at Maximum Manifold Spacing | R49: : | S49: 3.5 | T49: m
A52: 3. Unloading Performance | G52: 1. Unloading Flow Rate (Unloading Arm) | U52: 1. Unloading Flow Rate (Ship Manifold)
U53: **The actual operation flow shall be following Terminal maximum capability**
G54: Case | H54: No. of Arm | J54: Arm Arrangement | O54: Maximum Flowrate (m3/hr) (Normal operating condition) | R54: Maximum Manifold Pressure (barg) | U54: Case | V54: No. of Manifold | X54: Manifold Arrangement | AC54: Maximum Flowrate (m3/hr) | AF54: Maximum Manifold Pressure (barg)
J55: H | K55: G | L55: I | M55: F | N55: E | X55: L1 | Y55: L2 | Z55: V | AA55: L3 | AB55: L4
G56: 1 | H56: 5 | J56: O | K56: O | L56: O | M56: O | N56: O | O56: 14000 | R56: Normal Operating 5.0 bar (Liquid ) / 0.2 bar(Vapor return) | U56: 1 | V56: 5 | X56: O | Y56: O | Z56: O | AA56: O | AB56: O
G57: 2 | H57: 4 | J57: O | K57: O | L57: O | M57: O | N57: X | O57: 10500 | U57: 2 | V57: 4 | X57: O | Y57: O | Z57: O | AA57: O | AB57: X
...

Sheet page 5
A1: Confirmation List Between Ship-Shore (Berth # 1) | AU1: Page
AU2: 6 / 9
A3: Items | G3: Shore Specification | U3: Ship Specification | AI3: Remarks
A4: V. Unloading Arm / Cargo Pump / Compressor
A5: 4. Unloading Arm Working Range | G5: 1. Working Area | T5: (unit : m) | AH5: (unit : m) | AV5: (unit : m)
G6: (1) Working Range of Unloading Arm | U6: (1) Unloading Arm Compatibility | AI6: (2) Unloading Arm Moving Area
AB7: Reference Page1 Ship Major Dimensions
H8: Item | L8: From | P8: Operation | R8: Maximum | V8: Manifold heigh above BL | AB8: ='page 1'!AD30 -> 0
H9: Working Range of Unloading Arm | L9: High (above CDL) | P9: 27.5 | R9: 30.5 | V9: Ballast draft | AB9: ='page 1'!AD33 -> 0
L10: Low (above CDL) | P10: 17.5 | V10: Loaded draft | AB10: ='page 1'!AD34 -> 0
H11: Tide Level | L11: High (above CDL) | P11: 3.5 | V11: Safety clearance (m) | AB11: Normal | AE11: With Heave & List
L12: Low (above CDL) | P12: 0.5 | V12: Upper Position | AB12: =P9-(AB8-AB9+P11) -> 24 | AE12: =AB12-0.5 -> 23.5
H13: Heave & List | P13: 0.5 | V13: Lower Position | AB13: =AB8-AB10-P10 -> -17.5 | AE13: =AB13-0.5 -> -18
H14: ※ 1. Operation : Working range of Normal without any Alarm | V14: Result | AA14: =IF(OR(AB12<0,AE12<0,AB13<0,AE13<0),"**Unacceptable**","Acceptable") -> **Unacceptable**
H15: 2. Maximum : Working range of Maximum with Alarm
AI30: Terminal
AI31: 1. Nitrogen Air (For Unloading Arm Purging Purpose)
AI32: (1) Service Pressure | AL32: : | AM32: 7 | AN32: barg | AO32: (Max 17.2 barg)
AI33: (2) Service Point | AL33: : | AM33: At the APEX of all arms & lower part triple swivel assembly of liquid arms
AM34: **Reference Figure of Service Point
AI39: Vessel
AI40: 1. Nitrogen Air (For Manifold Purging Purpose)
AI41: (1) Will the ship provide nitrogen for line purging purpose? | AR41: :
AI42: 2. Fresh water (For Manifold Deicing Purpose)
AI43: (1) Will the ship provide fresh water for manifold deicing purpose? | AR43: :
A45: VI. Emergency Shut Down System
A46: 1. Optical Fiber System | G46: 1. Optical Fibre System (Primary System) | U46: 1. Optical Fibre System | AI46: Table 1.Optical Fiber System Signal Arrangement (Shore Side / Ship Side)
G47: (1) Manufacture | K47: : | L47: Trelleborg | U47: (1) Manufacture | Y47: : | AI47: Ferrule No. | AK47: Shore Side | AQ47: Ship Side
G48: (2) Connector Type | K48: : | L48: FO type 6 cores | U48: (2) Connector Type | Y48: : | AK48: Signal | AN48: Direction | AQ48: Signal | AT48: Direction
G49: (3) Cable Reel Position | K49: : | L49: 23.21 | M49: m Aft from the Vapour Arm | U49: (3) Connector Box Position | Y49: : | AA49: m from the vapour line center (Fwd = minus - /Af t= plus +) | AI49: 1 | AK49: Telephone Channel | AN49: Ship > Shore
G50: (4) Cable Length | K50: : | L50: 50 | M50: m | U50: (4) Signal Arrangement | Y50: : | Z50: Refer to Table 1 on the right column | AI50: 2 | AK50: Telephone Channel | AN50: Shore > Ship
G51: (5) Signal Arrangement | K51: : | L51: Refer to table 1 right side | AI51: 3 | AK51: ESD Channel | AN51: Ship > Shore
AI52: 4 | AK52: ESD Channel | AN52: Shore > Ship
A53: 2. Electric System | G53: 1. Electric System (Secondary System) | U53: 1. Electric System | AI53: 5 | AK53: Spare | AN53: Ship > Shore
G54: (1) Manufacture | K54: : | L54: Trelleborg | U54: (1) Manufacture | Y54: : | AI54: 6 | AK54: Spare | AN54: Shore > Ship
G55: (2) Connector Type | K55: : | L55: Electric connector 37-way receptacle | U55: (2) Connector Type | Y55: : | AI55: Table 2.Electric System Signal Arrangement (Shore Side / Ship Side)
G56: (3) Cable Reel Position | K56: : | L56: 21.82 | M56: m Aft from the Vapour Arm | U56: (3) Connector Box Position | Y56: : | AA56: m from the vapour line center (Fwd = minus - /Af t= plus +) | AI56: Pin No. | AK56: Shore Side | AP56: Pin No. | AR56: Ship Side
G57: (4) Cable Length | K57: : | L57: 50 | M57: m | U57: (4) Signal Arrangement | Y57: : | Z57: Refer to Table 2 on the right column | AI57: 1,2 | AK57: NOT USED | AP57: 1,2
G58: (5) Signal Arrangement | K58: : | L58: Refer to table 2 right side | AI58: 3,4 | AK58: SPARE | AP58: 3,4
A59: 3. Pneumatic System | G59: 1. Pneumatic System | U59: 1. Pneumatic System | AI59: 5,6 | AK59: ELEC TEL HOT PHONE | AP59: 5,6
...

Sheet page 6
A1: Confirmation List Between Ship-Shore (Berth # 1) | AN1: Page
AN2: 9 / 9
A3: Items | G3: Shore Specification | U3: Ship Specification | AD3: Remarks
A4: VII. CTMS On board
A5: CTMS On board
A6: 1. Level measurement devices (Primary) | G6: 1. Terminal Rule | U6: 1. CTMS On board
G7: (1) Accuracy | I7: : | J7: Equal to or better than (+ 7.5) mm. | U7: (1) Type | X7: : | AA7: =IF(Y9>7.5,"**Unacceptable**","Acceptable") -> Acceptable
U8: (2) Manufacturer | X8: :
G9: 2. Buyer's Requirement | U9: (3) Accuracy ± | X9: :
G10: (1) Accuracy | I10: : | J10: as per Map Ta Phut Terminal 1 | U10: (4) Certified by | X10: :
U11: (5) Issued Date | X11: :
A14: 2. Level measurement devices (Secondary) | G14: 1. Terminal Rule | U14: 1. CTMS On board
G15: (1) Accuracy | I15: : | J15: Equal to or better than (+ 7.5) mm. | U15: (1) Type | X15: : | AA15: =IF(Y17>7.5,"**Unacceptable**","Acceptable") -> Acceptable
U16: (2) Manufacturer | X16: :
G17: 2. Buyer's Requirement | U17: (3) Accuracy ± | X17: :
G18: (1) Accuracy | I18: : | J18: as per Map Ta Phut Terminal 1 | U18: (4) Certified by | X18: :
U19: (5) Issued Date | X19: :
A22: 3. Temperature measurement devices | G22: 1. Terminal Rule | U22: 1. CTMS On board
G23: (1) Accuracy | I23: : | J23: equal to or better than (+ 0.2) degrees celsius (at temp. range -145 to -165 °C) | U23: (1) Accuracy (at temp. range) | AA23: =IF(OR(Y24>0.2,Y25>1.5),"**Unacceptable**","Acceptable") -> Acceptable
I24: : | J24: equal to or better than (+ 1.5) degrees celsius (at temp. range +50 to -145 °C) | X24: : | Z24: (at temp. range -145 to -165 °C)
X25: : | Z25: (at temp. range +50 to -145 °C)
G26: 2. Buyer's Requirement | U26: (2) Certified by | X26: :
G27: (1) Accuracy | I27: : | J27: as per Map Ta Phut Terminal 1 | U27: (3) Issued Date | X27: :
A31: 4. Pressure measurement devices | G31: 1. Terminal Rule | U31: 1. CTMS On board
G32: (1) Accuracy | I32: : | J32: Accuracy in measuring the absolute pressure of the LNG vapour on each | U32: (1) Accuracy ± (%) | X32: : | AA32: =IF(Y32>1,"**Unacceptable**","Acceptable") -> Acceptable
J33: LNG tank shall be equal to or better than (± 1%) of the measuring range | U33: (2) Certified by | X33: :
U34: (3) Issued Date | X34: :
G35: 2. Buyer's Requirement
G36: (1) Accuracy | I36: : | J36: As per Map Ta Phut Terminal 1
A38: VIII. Fire Fighting System
A39: Fire Fighting System
G40: 1. Loading Platform | U40: Vessel Side
G41: (1) Fire Monitor | U41: (1)
G42: (2) Fire Hydrant & Host Reel | U42: (2)
G43: (3) Portable Fire Extinguisher | U43: (3)
G44: (4) Flame & Gas Detector | U44: (4)
G45: (5) Internation Ship Shore Connection | U45: (5)
G46: (6) Water Curtain | U46: (6)
G47: 2. Impoundment Pit | U47: (7)
G48: (1) Flame & Gas Detector | U48: (8)
...

Sheet Appendix A
A1: Appendix A : Mooring Layout size
B4: Mooring Pattern : Berth 1
B31: FWD : X/X/X/X :::::::: X/X/X/X AFT
B37: Mooring Pattern : Berth 2 (future)

Sheet Appendix B
A1: Appendix B : Spool Piece Drawing
B3: Terminal
B26: Ship
B28: ="SDPs on board of "&UPPER('page 1'!AC7) -> SDPs on board of
B30: Outside diameter | H30: : | M30: mm | O30: =IF(OR(I30<595,I30>598.5),"**Unacceptable**","Acceptable") -> **Unacceptable**
B33: Flage Thickness | H33: : | M33: mm | O33: =IF(OR(I33<36.6,I33>41),"**Unacceptable**","Acceptable") -> **Unacceptable**
B36: Raised Face | H36: : | M36: mm | O36: =IF(OR(I36<460,I36>470),"**Unacceptable**","Acceptable") -> **Unacceptable**
B39: Inside Diameter | H39: : | M39: mm | O39: =IF(OR(I39>387,I39=0),"**Unacceptable**","Acceptable") -> **Unacceptable**
B42: Surface Finish | H42: : | M42: Max | N42: Ra | O42: =IF(OR(I43<3.2,I42>12.5),"**Unacceptable**","Acceptable") -> **Unacceptable**
M43: Min
B45: Actual SDP on board (STB) | H45: : | M45: Units
B48: *Remark* The SDP or RDP onboard (shore side) must be RAISE FACE TYPE ONLY!
B50: The number of unloading arm will be connected: 4L - 3L - V - 2L - 1L
